Workbook

Sheet Rules
A1: Hold My Rings — League Keeper & Draft Rules
A2: # | B2: Rule | C2: Example / Exception
A3: KEEPER BASICS
A4: 1 | B4: Each team may keep two players.
A5: 2 | B5: A keeper costs the round he was drafted in the prior year — unless he has been kept multiple years.
A6: 3 | B6: Each additional year you keep a player, his keeper cost moves up one round.
A7: DRAFT ORDER
A8: 4 | B8: Draft order follows final regular season standings for teams that miss the playoffs.
A9: 5 | B9: As teams are eliminated in the playoffs, the team with the better record picks later. | C9: Example: Both eliminated in the quarterfinal — Team 1 (9-5) gets pick 6, Team 2 (7-7) gets pick 5.
A10: 6 | B10: If records are tied, the team with more regular season points picks later.
A11: KEEPER DRAFT POSITION
A12: 7 | B12: A keeper claimed off waivers last season costs an 8th round pick. | C12: Exception: if you originally drafted him, he keeps his original draft spot — waiver rules do not apply.
A13: 8 | B13: Keeping two players from the same round: the higher-ranked player (Yahoo rankings) costs one round earlier; the other keeps that round. | C13: Example: Two 3rd rounders — the better player costs a 2nd, the other a 3rd.
A14: 9 | B14: Keeping two 1st rounders: the higher-ranked player (Yahoo) costs a 1st, the other a 2nd.
A15: 10 | B15: A keeper acquired by trade costs the round he was drafted in the prior year. | C15: Exception: if he was claimed off waivers before the trade, he costs an 8th round pick.
A16: TRADING
A17: 11 | B17: Roster players and draft picks may be traded before the draft.
A18: 12 | B18: Pick limits: 16 picks max (one per draft selection), and 14 minimum if you keep two players.
A19: 13 | B19: Offseason trading closes one week before keeper selections are due.
A20: 14 | B20: Waiver-claimed players may be traded at 8th round keeper value.
A21: COMMISSIONER'S NOTE
B22: Keepers shouldn't be a fight — the system rewards good drafting and smart in-season moves. Raising keeper cost by a round each year makes you weigh a player's real value and frees up players who used to be locked away. Suggestions welcome.

Sheet League Settings
A1: 2025 League Settings & Scoring
A2: LEAGUE & DRAFT SETTINGS
A3: Draft Type | B3: Live Standard Draft
A4: Max Teams | B4: 10
A5: Live Draft Pick Time | B5: 1 minute, 15 seconds
A6: Trade End Date | B6: December 5, 2026
A7: Waiver Time | B7: 2 days
A8: Waiver Type | B8: FAB w/ continual rolling list tiebreak
A9: Weekly Waivers | B9: Game time - Tuesday
A10: Injured players from waivers/FA direct to IR slot | B10: Yes
A11: Playoffs | B11: 6 teams - Weeks 15, 16 and 17 (ends Monday, Dec 29)
A12: Playoff Tie-Breaker | B12: Best regular season record vs. opponent wins
A13: Playoff Reseeding | B13: Yes
A14: Roster Positions | B14: QB, WR, WR, WR, RB, RB, TE, W/R/T, K, DEF, BN, BN, BN, BN, BN, BN, IR, IR
A16: SCORING - OFFENSE
A17: Category | B17: League Value | C17: Yahoo Default Value
A18: Passing Yards | B18: 25 yards per point; 6 points at 400 yards
A19: Passing Touchdowns | B19: 6 | C19: 4
A20: Interceptions | B20: -2 | C20: -1
A21: Rushing Yards | B21: 10 yards per point; 6 points at 200 yards
A22: Rushing Touchdowns | B22: 6
A23: Receptions | B23: 1 | C23: 0.5
A24: Receiving Yards | B24: 10 yards per point; 6 points at 200 yards
A25: Receiving Touchdowns | B25: 6
A26: Return Touchdowns | B26: 6
A27: 2-Point Conversions | B27: 2
A28: Fumbles Lost | B28: -2
A29: Offensive Fumble Return TD | B29: 6
A31: SCORING - KICKERS
A32: Category | B32: League Value | C32: Yahoo Default Value
A33: Field Goals 0-19 Yards | B33: 3
A34: Field Goals 20-29 Yards | B34: 3
A35: Field Goals 30-39 Yards | B35: 3
A36: Field Goals 40-49 Yards | B36: 4
A37: Field Goals 50+ Yards | B37: 5
A38: Point After Attempt Made | B38: 1
A40: SCORING - DEFENSE / SPECIAL TEAMS
A41: Category | B41: League Value | C41: Yahoo Default Value
A42: Sack | B42: 1
A43: Interception | B43: 2
...

Sheet Draft Order-Traded Picks
A1: Traded Pick | B1: 2026 DRAFT ORDER AND TRADED PICKS
A2: Cell = new owner | B2: Shawn jen's Legendary Team | C2: Joe The real sultan | D2: John Aarons got a Gun | E2: Ben Prestige Worldwide | F2: Chris Colin for the win | G2: Kevin The V&G Express | H2: Nate Maye I put it in your Boutte? | I2: JR Leeroy Judkins | J2: Robert Any given Sunday | K2: AJ Saquon deez nutz
A3: ROUND 1
A4: ROUND 2 | I4: jen's Legendary Team | J4: jen's Legendary Team
A5: ROUND 3
A6: ROUND 4
A7: ROUND 5
A8: ROUND 6
A9: ROUND 7 | I9: jen's Legendary Team
A10: ROUND 8
A11: ROUND 9
A12: ROUND 10 | B12: Leeroy Judkins
A13: ROUND 11 | B13: Any given Sunday
A14: ROUND 12 | B14: Leeroy Judkins
A15: ROUND 13
A16: ROUND 14
A17: ROUND 15
A18: ROUND 16
B20: 2025 TRADES
B21: Team | C21: Received | D21: Pos
B22: jen's Legendary Team | C22: Kyle Monangai (Chi) | D22: RB
C23: Round 7 Pick
B24: Leeroy Judkins | C24: Omarion Hampton (LAC) | D24: RB
C25: Round 12 Pick
B26: Any given Sunday | C26: Puka Nacua (LAR) | D26: WR
C27: Round 11 Pick
B28: jen's Legendary Team | C28: Xavier Worthy (KC) | D28: WR
C29: Round 2 Pick
B30: Leeroy Judkins | C30: Rhamondre Stevenson (NE) | D30: RB
C31: CeeDee Lamb (Dal) | D31: WR
C32: Round 10 Pick
B33: jen's Legendary Team | C33: Jaylen Warren (Pit) | D33: RB
C34: Round 2 Pick

Sheet 2026 Keeper Draft Spot
A1: 2026 KEEPER DRAFT SPOT - cost to keep each player next season
A2: Shawn jen's Legendary Team | B2: AJ Saquon deez nutz | C2: Robert Any given Sunday | D2: Chris Colin for the win | E2: John Aarons got a Gun | F2: Kevin The V&G Express | G2: JR Leeroy Judkins | H2: Joe The real sultan | I2: Ben Prestige Worldwide | J2: Nate Maye I put it in your Boutte?
A3: Alvin Kamara - 3rd | B3: Jahmyr Gibbs - 1st | C3: Amon-Ra St. Brown - 1st | D3: Derrick Henry - 1st | E3: Bijan Robinson - 1st | F3: Drake London - 1st | G3: Ashton Jeanty - 1st | H3: Christian McCaffrey - 1st | I3: Josh Jacobs - 1st | J3: Saquon Barkley - 1st
A4: Kenneth Walker III - 4th | B4: Chase Brown - 2nd | C4: Jalen Hurts - 2nd | D4: A.J. Brown - 2nd | E4: Chuba Hubbard - 3rd | F4: TreVeyon Henderson - 3rd | G4: CeeDee Lamb - 1st | H4: Lamar Jackson - 2nd | I4: Mike Evans - 2nd | J4: George Kittle - 2nd
A5: Xavier Worthy - 5th | B5: Tyreek Hill - 3rd | C5: Jonathan Taylor - 2nd | D5: James Cook III - 3rd | E5: Justin Jefferson - 5th | F5: George Pickens - 4th | G5: Trey McBride - 2nd | H5: Malik Nabers - 2nd | I5: Tee Higgins - 2nd | J5: Ja'Marr Chase - 2nd
A6: Jaylen Warren - 7th | B6: Davante Adams - 4th | C6: Puka Nacua - 2nd | D6: Zay Flowers - 4th | E6: Rome Odunze - 7th | F6: Courtland Sutton - 5th | G6: Omarion Hampton - 3rd | H6: Garrett Wilson - 4th | I6: Breece Hall - 4th | J6: RJ Harvey - 4th
A7: Alec Pierce - 8th | B7: DeVonta Smith - 5th | C7: Terry McLaurin - 3rd | D7: Jordan Addison - 5th | E7: Bam Knight - 8th | F7: Emeka Egbuka - 6th | G7: Jaylen Waddle - 6th | H7: D'Andre Swift - 5th | I7: Tetairoa McMillan - 5th | J7: Ricky Pearsall - 5th
A8: Brian Thomas Jr. - 8th | B8: Travis Kelce - 6th | C8: Marvin Harrison Jr. - 4th | D8: Tony Pollard - 5th | E8: Brenton Strange - 8th | F8: Kyren Williams - 6th | G8: Stefon Diggs - 7th | H8: Chris Olave - 6th | I8: Aaron Jones Sr. - 6th | J8: Travis Hunter - 6th
A9: Cam Little - 8th | B9: AJ Barner - 8th | C9: David Montgomery - 5th | D9: Tucker Kraft - 7th | E9: Chase McLaughlin - 8th | F9: Blake Corum - 8th | G9: Bhayshul Tuten - 8th | H9: Adonai Mitchell - 8th | I9: Mark Andrews - 7th | J9: Brock Purdy - 8th
A10: Devin Singletary - 8th | B10: Caleb Williams - 8th | C10: Rashee Rice - 7th | D10: Bo Nix - 8th | E10: Chimere Dike - 8th | F10: Christian Watson - 8th | G10: Braelon Allen - 8th | H10: Isiah Pacheco - 8th | I10: DJ Moore - 8th | J10: Devaughn Vele - 8th
A11: Falcons - 8th | B11: Chris Boswell - 8th | C11: Dalton Schultz - 8th | D11: Buccaneers - 8th | E11: Hassan Haskins - 8th | F11: Devin Neal - 8th | G11: Harold Fannin Jr. - 8th | H11: Jayden Daniels - 8th | I11: Dak Prescott - 8th | J11: Eagles - 8th
A12: Kyle Monangai - 8th | B12: Jaxon Smith-Njigba - 8th | C12: Juwan Johnson - 8th | D12: Cade Otton - 8th | E12: Jaguars - 8th | F12: Evan McPherson - 8th | G12: Isaac TeSlaa - 8th | H12: Luther Burden III - 8th | I12: Deebo Samuel Sr. - 8th | J12: J.K. Dobbins - 8th
A13: Kyle Pitts Sr. - 8th | B13: Jaxson Dart - 8th | C13: Trevor Lawrence - 8th | D13: Jordan Mason - 8th | E13: Jakobi Meyers - 8th | F13: Jacoby Brissett - 8th | G13: Kaleb Johnson - 8th | H13: Matt Prater - 8th | I13: Jerry Jeudy - 8th | J13: Michael Wilson - 8th
... A18: Jayden Reed - 11th | B18: Joe Mixon - 11th | C18: Ka'imi Fairbairn - 16th | D18: Hunter Henry - 12th | E18: Rashid Shaheed - 12th | F18: Tyler Warren - 10th | G18: Tyler Allgeier - 8th | H18: Brandon Aiyuk - 11th | I18: Brandon Aubrey - 12th | J18: Baker Mayfield - 11th
A19: T.J. Hockenson - 12th | B19: Chris Godwin Jr. - 12th | D19: Cameron Dicker - 14th | G19: Josh Allen - 10th | H19: Brock Bowers - 11th | I19: Bills - 15th | J19: Javonte Williams - 12th
B20: Woody Marks - 14th | G20: Quinshon Judkins - 10th | H20: Justin Herbert - 13th | I20: Dallas Goedert - 16th | J20: Jake Ferguson - 14th

Sheet jen's Legendary Team
A1: JEN'S LEGENDARY TEAM ★ Shawn
A2: 2025 Slot | B2: Player | C2: Pos | D2: NFL | E2: 2026 ADP (adj) | F2: ADP Round | G2: Keeper Cost (Rd) | H2: Value (Rd) | I2: Kept in 2025 | J2: How acquired | L2: TEAM SUMMARY
A3: Waiver add | B3: Matthew Stafford | C3: QB | D3: LAR | E3: 69.1 | F3: 7 | G3: 8 | H3: 1 | J3: Waiver claim | L3: Players | M3: 17
A4: Round 7 | B4: Jaylen Warren | C4: RB | D4: PIT | E4: 64.8 | F4: 7 | G4: 7 | H4: 0 | J4: Acquired by trade | L4: Kept in 2025 (*) | M4: 2
A5: Waiver add | B5: Kyle Monangai | C5: RB | D5: CHI | E5: 111.5 | F5: 12 | G5: 8 | H5: -4 | J5: Acquired by trade | L5: Avg ADP (league-adj) | M5: 93.608333
A6: Round 8 | B6: Zach Charbonnet | C6: RB | D6: SEA | E6: 139 | F6: 14 | G6: 8 | H6: -6 | J6: Drafted 2025 | L6: Best value (Rd) | M6: 2
A7: Round 3 | B7: Alvin Kamara | C7: RB | D7: NO | E7: 142.9 | F7: 15 | G7: 3 | H7: -12 | J7: Drafted 2025 | L7: Best value player | M7: Alec Pierce
A8: Waiver add | B8: Devin Singletary | C8: RB | D8: NYG | G8: 8 | J8: Waiver claim | L8: Players with no ADP | M8: 5
A9: Round 4 | B9: Kenneth Walker III | C9: RB | D9: KC | G9: 4 | J9: Drafted 2025 | L9: Waiver adds (8th rd) | M9: 7
A10: Waiver add | B10: Alec Pierce | C10: WR | D10: IND | E10: 58.4 | F10: 6 | G10: 8 | H10: 2 | J10: Waiver claim
A11: Round 10 | B11: Michael Pittman Jr. | C11: WR | D11: PIT | E11: 73.5 | F11: 8 | G11: 10 | H11: 2 | J11: Drafted 2025 | L11: Team key (do not edit) | M11: jen's Legendary Team (Shawn)
A12: Round 9 | B12: Brian Thomas Jr. | C12: WR | D12: JAX | E12: 73.9 | F12: 8 | G12: 8 | H12: 0 | I12: * | J12: Drafted 2025 | L12: Team name key | M12: jen's Legendary Team
A13: Round 11 | B13: Jayden Reed | C13: WR | D13: GB | E13: 93.9 | F13: 10 | G13: 11 | H13: 1 | J13: Drafted 2025 | L13: Draft header key | M13: Shawn jen's Legendary Team
A14: Round 5 | B14: Xavier Worthy | C14: WR | D14: KC | E14: 106.2 | F14: 11 | G14: 5 | H14: -6 | J14: Acquired by trade
A15: Waiver add | B15: Romeo Doubs | C15: WR | D15: NE | E15: 112.6 | F15: 12 | G15: 8 | H15: -4 | J15: Waiver claim
A16: Waiver add | B16: Kyle Pitts Sr. | C16: TE | D16: ATL | E16: 77.5 | F16: 8 | G16: 8 | H16: 0 | J16: Waiver claim
A17: Round 13 | B17: T.J. Hockenson | C17: TE | D17: MIN | G17: 12 | I17: * | J17: Drafted 2025
A18: Waiver add | B18: Cam Little | C18: K | D18: JAX | G18: 8 | J18: Waiver claim
A19: Waiver add | B19: Falcons | C19: DEF | D19: ATL | G19: 8 | J19: Waiver claim
A21: POSITION COUNTS
A22: QB | B22: 1
A23: RB | B23: 6
A24: WR | B24: 6
A25: TE | B25: 2
A26: K | B26: 1
A27: DEF | B27: 1
A28: TOTAL | B28: =SUM(B22:B27) -> 17
A30: KEEPER PICKER - choose up to 2 (rules applied automatically)
A31: 2025 Slot | B31: Keeper (pick from list) | C31: Pos | D31: NFL | E31: ADP | F31: ADP Rd | G31: Base Cost (Rd) | H31: Adj Cost (Rd) | I31: Round Given Up | J31: Value (Rd)
A32: =IF($B32="","",IFERROR(_xlfn.XLOOKUP($B32,$B$3:$B$20,$A$3:$A$20),"")) | C32: =IF($B32="","",IFERROR(_xlfn.XLOOKUP($B32,$B$3:$B$20,$C$3:$C$20),"")) | D32: =IF($B32="","",IFERROR(_xlfn.XLOOKUP($B32,$B$3:$B$20,$D$3:$D$20),"")) | E32: =IF($B32="","",IFERROR(_xlfn.XLOOKUP($B32,$B$3:$B$20,$E$3:$E$20),"")) | F32: =IF($B32="","",IFERROR(_xlfn.XLOOKUP($B32,$B$3:$B$20,$F$3:$F$20),"")) | G32: =IF($B32="","",IFERROR(_xlfn.XLOOKUP($B32,$B$3:$B$20,$G$3:$G$20),"")) | H32: =IF($B32="","",IF(OR($B33="",$G32<>$G33),$G32,IF($G32=1,IF($E32<=$E33,1,2),IF($E32<=$E33,MAX(1,$G32-1),$G32)))) | I32: =IF($H32="","","Round "&$H32) | J32: =IF(OR($B32="",$F32=""),"",$F32-$H32)
A33: =IF($B33="","",IFERROR(_xlfn.XLOOKUP($B33,$B$3:$B$20,$A$3:$A$20),"")) | C33: =IF($B33="","",IFERROR(_xlfn.XLOOKUP($B33,$B$3:$B$20,$C$3:$C$20),"")) | D33: =IF($B33="","",IFERROR(_xlfn.XLOOKUP($B33,$B$3:$B$20,$D$3:$D$20),"")) | E33: =IF($B33="","",IFERROR(_xlfn.XLOOKUP($B33,$B$3:$B$20,$E$3:$E$20),"")) | F33: =IF($B33="","",IFERROR(_xlfn.XLOOKUP($B33,$B$3:$B$20,$F$3:$F$20),"")) | G33: =IF($B33="","",IFERROR(_xlfn.XLOOKUP($B33,$B$3:$B$20,$G$3:$G$20),"")) | H33: =IF($B33="","",IF(OR($B32="",$G33<>$G32),$G33,IF($G33=1,IF($E33<=$E32,1,2),IF($E33<=$E32,MAX(1,$G33-1),$G33)))) | I33: =IF($H33="","","Round "&$H33) | J33: =IF(OR($B33="",$F33=""),"",$F33-$H33)
A34: TOTALS | G34: =IF(COUNT($G$32:$G$33)=0,"",SUM($G$32:$G$33)) | H34: =IF(COUNT($H$32:$H$33)=0,"",SUM($H$32:$H$33)) | J34: =IF(COUNT($J$32:$J$33)=0,"",SUM($J$32:$J$33))
A36: RULES & SOURCES APPLIED ON THIS TAB
A37: Keeper cost = the round the player was drafted in 2025. A player kept in 2025 costs one round earlier. A player claimed off waivers costs an 8th (unless you originally drafted him). A keeper acquired by trade costs his original 2025 round.
A38: Two keepers with the same cost: the higher-ranked player moves up one round, the other keeps that round. Two 1st rounders cost a 1st and a 2nd. "Higher-ranked" is resolved here by league-adjusted ADP (lower ADP = higher rank).
A39: Draft capital: 16 picks max, less picks traded away, plus picks acquired, less keepers selected. Minimum 14 picks if you keep two.
A40: {="Rounds traded away: "&_xlfn.LET(_xlpm.sl,MATCH(TRUE,EXACT('Draft Order-Traded Picks'!$B$2:$K$2,$M$13),0),_xlpm.g,INDEX('Draft Order-Traded Picks'!$B$3:$K$18,_xlfn.SEQUENCE(16),_xlpm.sl),IF(SUMPRODUCT(--(_xlpm.g<>""))=0,"none",_xlfn.TEXTJOIN(", ",TRUE,IF(_xlpm.g<>"","Rd "&_xlfn.SEQUENCE(16),""))))} -> Rounds traded away: Rd 10, Rd 11, Rd 12
A41: {="Rounds acquired: "&_xlfn.LET(_xlpm.m,MMULT(--EXACT('Draft Order-Traded Picks'!$B$3:$K$18,$M$12),_xlfn.SEQUENCE(10,1,1,0)),IF(SUM(_xlpm.m)=0,"none",_xlfn.TEXTJOIN(", ",TRUE,IF(_xlpm.m>0,"Rd "&_xlfn.SEQUENCE(16)&IF(_xlpm.m>1," (x"&_xlpm.m&")",""),""))&" - "&SUM(_xlpm.m)&" pick(s) total"))} -> Rounds acquired: Rd 2 (x2), Rd 7 - 3 pick(s) total
A42: Value (Rd) = ADP Round minus Keeper Cost Round; positive = bargain. ADP is the 2026 full-PPR board adjusted for this league's 6-point passing TD (QBs move up 12 picks), a static snapshot taken July 2026. The roster table, team summary and position counts above are hard-coded values - they no longer recalculate. The keeper picker below is live and applies the keeper rules automatically; the traded-pick lines read from the 'Draft Order-Traded Picks' tab, so they update if more picks are traded.

Sheet The real sultan
A1: THE REAL SULTAN ★ Joe
A2: 2025 Slot | B2: Player | C2: Pos | D2: NFL | E2: 2026 ADP (adj) | F2: ADP Round | G2: Keeper Cost (Rd) | H2: Value (Rd) | I2: Kept in 2025 | J2: How acquired | L2: TEAM SUMMARY
A3: Round 2 | B3: Lamar Jackson | C3: QB | D3: BAL | E3: 43.5 | F3: 5 | G3: 2 | H3: -3 | J3: Drafted 2025 | L3: Players | M3: 18
A4: Waiver add | B4: Jayden Daniels | C4: QB | D4: WAS | E4: 60 | F4: 6 | G4: 8 | H4: 2 | J4: Waiver claim | L4: Kept in 2025 (*) | M4: 2
A5: Round 13 | B5: Justin Herbert | C5: QB | D5: LAC | E5: 93.2 | F5: 10 | G5: 13 | H5: 3 | J5: Drafted 2025 | L5: Avg ADP (league-adj) | M5: 60.921429
A6: Round 1 | B6: Christian McCaffrey | C6: RB | D6: SF | E6: 6.4 | F6: 1 | G6: 1 | H6: 0 | J6: Drafted 2025 | L6: Best value (Rd) | M6: 7
A7: Round 9 | B7: Travis Etienne Jr. | C7: RB | D7: NO | E7: 41.5 | F7: 5 | G7: 9 | H7: 4 | J7: Drafted 2025 | L7: Best value player | M7: Brock Bowers
A8: Round 5 | B8: D'Andre Swift | C8: RB | D8: CHI | E8: 46 | F8: 5 | G8: 5 | H8: 0 | J8: Drafted 2025 | L8: Players with no ADP | M8: 4
A9: Waiver add | B9: Isiah Pacheco | C9: RB | D9: DET | E9: 153.9 | F9: 16 | G9: 8 | H9: -8 | J9: Waiver claim | L9: Waiver adds (8th rd) | M9: 7
A10: Round 6 | B10: Chris Olave | C10: WR | D10: NO | E10: 21.5 | F10: 3 | G10: 6 | H10: 3 | J10: Drafted 2025
A11: Round 4 | B11: Garrett Wilson | C11: WR | D11: NYJ | E11: 27.8 | F11: 3 | G11: 4 | H11: 1 | J11: Drafted 2025 | L11: Team key (do not edit) | M11: The real sultan (Joe)
A12: Round 3 | B12: Malik Nabers | C12: WR | D12: NYG | E12: 28.4 | F12: 3 | G12: 2 | H12: -1 | I12: * | J12: Drafted 2025 | L12: Team name key | M12: The real sultan
A13: Waiver add | B13: Luther Burden III | C13: WR | D13: CHI | E13: 58.4 | F13: 6 | G13: 8 | H13: 2 | J13: Waiver claim | L13: Draft header key | M13: Joe The real sultan
A14: Round 10 | B14: Khalil Shakir | C14: WR | D14: BUF | E14: 101.3 | F14: 11 | G14: 10 | H14: -1 | J14: Drafted 2025
A15: Waiver add | B15: Tre Tucker | C15: WR | D15: LV | E15: 133 | F15: 14 | G15: 8 | H15: -6 | J15: Waiver claim
A16: Waiver add | B16: Adonai Mitchell | C16: WR | D16: NYJ | G16: 8 | J16: Waiver claim
A17: Round 11 | B17: Brandon Aiyuk | C17: WR | D17: SF | G17: 11 | J17: Drafted 2025
A18: Round 12 | B18: Brock Bowers | C18: TE | D18: LV | E18: 38 | F18: 4 | G18: 11 | H18: 7 | I18: * | J18: Drafted 2025
A19: Waiver add | B19: Matt Prater | C19: K | D19: FA | G19: 8 | J19: Waiver claim
A20: Waiver add | B20: Texans | C20: DEF | D20: HOU | G20: 8 | J20: Waiver claim
A21: POSITION COUNTS
A22: QB | B22: 3
A23: RB | B23: 4
A24: WR | B24: 8
A25: TE | B25: 1
A26: K | B26: 1
A27: DEF | B27: 1
A28: TOTAL | B28: =SUM(B22:B27) -> 18
A30: KEEPER PICKER - choose up to 2 (rules applied automatically)
A31: 2025 Slot | B31: Keeper (pick from list) | C31: Pos | D31: NFL | E31: ADP | F31: ADP Rd | G31: Base Cost (Rd) | H31: Adj Cost (Rd) | I31: Round Given Up | J31: Value (Rd)
A32: =IF($B32="","",IFERROR(_xlfn.XLOOKUP($B32,$B$3:$B$20,$A$3:$A$20),"")) | C32: =IF($B32="","",IFERROR(_xlfn.XLOOKUP($B32,$B$3:$B$20,$C$3:$C$20),"")) | D32: =IF($B32="","",IFERROR(_xlfn.XLOOKUP($B32,$B$3:$B$20,$D$3:$D$20),"")) | E32: =IF($B32="","",IFERROR(_xlfn.XLOOKUP($B32,$B$3:$B$20,$E$3:$E$20),"")) | F32: =IF($B32="","",IFERROR(_xlfn.XLOOKUP($B32,$B$3:$B$20,$F$3:$F$20),"")) | G32: =IF($B32="","",IFERROR(_xlfn.XLOOKUP($B32,$B$3:$B$20,$G$3:$G$20),"")) | H32: =IF($B32="","",IF(OR($B33="",$G32<>$G33),$G32,IF($G32=1,IF($E32<=$E33,1,2),IF($E32<=$E33,MAX(1,$G32-1),$G32)))) | I32: =IF($H32="","","Round "&$H32) | J32: =IF(OR($B32="",$F32=""),"",$F32-$H32)
A33: =IF($B33="","",IFERROR(_xlfn.XLOOKUP($B33,$B$3:$B$20,$A$3:$A$20),"")) | C33: =IF($B33="","",IFERROR(_xlfn.XLOOKUP($B33,$B$3:$B$20,$C$3:$C$20),"")) | D33: =IF($B33="","",IFERROR(_xlfn.XLOOKUP($B33,$B$3:$B$20,$D$3:$D$20),"")) | E33: =IF($B33="","",IFERROR(_xlfn.XLOOKUP($B33,$B$3:$B$20,$E$3:$E$20),"")) | F33: =IF($B33="","",IFERROR(_xlfn.XLOOKUP($B33,$B$3:$B$20,$F$3:$F$20),"")) | G33: =IF($B33="","",IFERROR(_xlfn.XLOOKUP($B33,$B$3:$B$20,$G$3:$G$20),"")) | H33: =IF($B33="","",IF(OR($B32="",$G33<>$G32),$G33,IF($G33=1,IF($E33<=$E32,1,2),IF($E33<=$E32,MAX(1,$G33-1),$G33)))) | I33: =IF($H33="","","Round "&$H33) | J33: =IF(OR($B33="",$F33=""),"",$F33-$H33)
A34: TOTALS | G34: =IF(COUNT($G$32:$G$33)=0,"",SUM($G$32:$G$33)) | H34: =IF(COUNT($H$32:$H$33)=0,"",SUM($H$32:$H$33)) | J34: =IF(COUNT($J$32:$J$33)=0,"",SUM($J$32:$J$33))
A36: RULES & SOURCES APPLIED ON THIS TAB
A37: Keeper cost = the round the player was drafted in 2025. A player kept in 2025 costs one round earlier. A player claimed off waivers costs an 8th (unless you originally drafted him). A keeper acquired by trade costs his original 2025 round.
A38: Two keepers with the same cost: the higher-ranked player moves up one round, the other keeps that round. Two 1st rounders cost a 1st and a 2nd. "Higher-ranked" is resolved here by league-adjusted ADP (lower ADP = higher rank).
A39: Draft capital: 16 picks max, less picks traded away, plus picks acquired, less keepers selected. Minimum 14 picks if you keep two.
A40: {="Rounds traded away: "&_xlfn.LET(_xlpm.sl,MATCH(TRUE,EXACT('Draft Order-Traded Picks'!$B$2:$K$2,$M$13),0),_xlpm.g,INDEX('Draft Order-Traded Picks'!$B$3:$K$18,_xlfn.SEQUENCE(16),_xlpm.sl),IF(SUMPRODUCT(--(_xlpm.g<>""))=0,"none",_xlfn.TEXTJOIN(", ",TRUE,IF(_xlpm.g<>"","Rd "&_xlfn.SEQUENCE(16),""))))} -> Rounds traded away: none
A41: {="Rounds acquired: "&_xlfn.LET(_xlpm.m,MMULT(--EXACT('Draft Order-Traded Picks'!$B$3:$K$18,$M$12),_xlfn.SEQUENCE(10,1,1,0)),IF(SUM(_xlpm.m)=0,"none",_xlfn.TEXTJOIN(", ",TRUE,IF(_xlpm.m>0,"Rd "&_xlfn.SEQUENCE(16)&IF(_xlpm.m>1," (x"&_xlpm.m&")",""),""))&" - "&SUM(_xlpm.m)&" pick(s) total"))} -> Rounds acquired: none
A42: Value (Rd) = ADP Round minus Keeper Cost Round; positive = bargain. ADP is the 2026 full-PPR board adjusted for this league's 6-point passing TD (QBs move up 12 picks), a static snapshot taken July 2026. The roster table, team summary and position counts above are hard-coded values - they no longer recalculate. The keeper picker below is live and applies the keeper rules automatically; the traded-pick lines read from the 'Draft Order-Traded Picks' tab, so they update if more picks are traded.

Sheet Aarons got a Gun
A1: AARONS GOT A GUN ★ John
A2: 2025 Slot | B2: Player | C2: Pos | D2: NFL | E2: 2026 ADP (adj) | F2: ADP Round | G2: Keeper Cost (Rd) | H2: Value (Rd) | I2: Kept in 2025 | J2: How acquired | L2: TEAM SUMMARY
A3: Waiver add | B3: Jared Goff | C3: QB | D3: DET | E3: 93.8 | F3: 10 | G3: 8 | H3: -2 | J3: Waiver claim | L3: Players | M3: 16
A4: Round 1 | B4: Bijan Robinson | C4: RB | D4: ATL | E4: 1.7 | F4: 1 | G4: 1 | H4: 0 | I4: * | J4: Drafted 2025 | L4: Kept in 2025 (*) | M4: 2
A5: Round 3 | B5: Chuba Hubbard | C5: RB | D5: CAR | E5: 74.4 | F5: 8 | G5: 3 | H5: -5 | J5: Drafted 2025 | L5: Avg ADP (league-adj) | M5: 81.57
A6: Waiver add | B6: Kenny Gainwell | C6: RB | D6: TB | E6: 88.6 | F6: 9 | G6: 8 | H6: -1 | J6: Waiver claim | L6: Best value (Rd) | M6: 3
A7: Waiver add | B7: Tyjae Spears | C7: RB | D7: TEN | E7: 133.3 | F7: 14 | G7: 8 | H7: -6 | J7: Waiver claim | L7: Best value player | M7: Justin Jefferson
A8: Waiver add | B8: Bam Knight | C8: RB | D8: ARI | G8: 8 | J8: Waiver claim | L8: Players with no ADP | M8: 6
A9: Waiver add | B9: Hassan Haskins | C9: RB | D9: NE | G9: 8 | J9: Waiver claim | L9: Waiver adds (8th rd) | M9: 10
A10: Round 6 | B10: Justin Jefferson | C10: WR | D10: MIN | E10: 13 | F10: 2 | G10: 5 | H10: 3 | I10: * | J10: Drafted 2025
A11: Round 7 | B11: Rome Odunze | C11: WR | D11: CHI | E11: 49 | F11: 5 | G11: 7 | H11: 2 | J11: Drafted 2025 | L11: Team key (do not edit) | M11: Aarons got a Gun (John)
A12: Round 8 | B12: Jakobi Meyers | C12: WR | D12: JAX | E12: 83.5 | F12: 9 | G12: 8 | H12: -1 | J12: Drafted 2025 | L12: Team name key | M12: Aarons got a Gun
A13: Round 12 | B13: Rashid Shaheed | C13: WR | D13: SEA | E13: 127.6 | F13: 13 | G13: 12 | H13: -1 | J13: Drafted 2025 | L13: Draft header key | M13: John Aarons got a Gun
A14: Waiver add | B14: Chimere Dike | C14: WR | D14: TEN | E14: 150.8 | F14: 16 | G14: 8 | H14: -8 | J14: Waiver claim
A15: Waiver add | B15: Brenton Strange | C15: TE | D15: JAX | G15: 8 | J15: Waiver claim
A16: Waiver add | B16: Zach Ertz | C16: TE | D16: WAS | G16: 8 | J16: Waiver claim
A17: Waiver add | B17: Chase McLaughlin | C17: K | D17: TB | G17: 8 | J17: Waiver claim
A18: Waiver add | B18: Jaguars | C18: DEF | D18: JAX | G18: 8 | J18: Waiver claim
A21: POSITION COUNTS
A22: QB | B22: 1
A23: RB | B23: 6
A24: WR | B24: 5
A25: TE | B25: 2
A26: K | B26: 1
A27: DEF | B27: 1
A28: TOTAL | B28: =SUM(B22:B27) -> 16
A30: KEEPER PICKER - choose up to 2 (rules applied automatically)
A31: 2025 Slot | B31: Keeper (pick from list) | C31: Pos | D31: NFL | E31: ADP | F31: ADP Rd | G31: Base Cost (Rd) | H31: Adj Cost (Rd) | I31: Round Given Up | J31: Value (Rd)
A32: =IF($B32="","",IFERROR(_xlfn.XLOOKUP($B32,$B$3:$B$20,$A$3:$A$20),"")) | C32: =IF($B32="","",IFERROR(_xlfn.XLOOKUP($B32,$B$3:$B$20,$C$3:$C$20),"")) | D32: =IF($B32="","",IFERROR(_xlfn.XLOOKUP($B32,$B$3:$B$20,$D$3:$D$20),"")) | E32: =IF($B32="","",IFERROR(_xlfn.XLOOKUP($B32,$B$3:$B$20,$E$3:$E$20),"")) | F32: =IF($B32="","",IFERROR(_xlfn.XLOOKUP($B32,$B$3:$B$20,$F$3:$F$20),"")) | G32: =IF($B32="","",IFERROR(_xlfn.XLOOKUP($B32,$B$3:$B$20,$G$3:$G$20),"")) | H32: =IF($B32="","",IF(OR($B33="",$G32<>$G33),$G32,IF($G32=1,IF($E32<=$E33,1,2),IF($E32<=$E33,MAX(1,$G32-1),$G32)))) | I32: =IF($H32="","","Round "&$H32) | J32: =IF(OR($B32="",$F32=""),"",$F32-$H32)
A33: =IF($B33="","",IFERROR(_xlfn.XLOOKUP($B33,$B$3:$B$20,$A$3:$A$20),"")) | C33: =IF($B33="","",IFERROR(_xlfn.XLOOKUP($B33,$B$3:$B$20,$C$3:$C$20),"")) | D33: =IF($B33="","",IFERROR(_xlfn.XLOOKUP($B33,$B$3:$B$20,$D$3:$D$20),"")) | E33: =IF($B33="","",IFERROR(_xlfn.XLOOKUP($B33,$B$3:$B$20,$E$3:$E$20),"")) | F33: =IF($B33="","",IFERROR(_xlfn.XLOOKUP($B33,$B$3:$B$20,$F$3:$F$20),"")) | G33: =IF($B33="","",IFERROR(_xlfn.XLOOKUP($B33,$B$3:$B$20,$G$3:$G$20),"")) | H33: =IF($B33="","",IF(OR($B32="",$G33<>$G32),$G33,IF($G33=1,IF($E33<=$E32,1,2),IF($E33<=$E32,MAX(1,$G33-1),$G33)))) | I33: =IF($H33="","","Round "&$H33) | J33: =IF(OR($B33="",$F33=""),"",$F33-$H33)
A34: TOTALS | G34: =IF(COUNT($G$32:$G$33)=0,"",SUM($G$32:$G$33)) | H34: =IF(COUNT($H$32:$H$33)=0,"",SUM($H$32:$H$33)) | J34: =IF(COUNT($J$32:$J$33)=0,"",SUM($J$32:$J$33))
A36: RULES & SOURCES APPLIED ON THIS TAB
A37: Keeper cost = the round the player was drafted in 2025. A player kept in 2025 costs one round earlier. A player claimed off waivers costs an 8th (unless you originally drafted him). A keeper acquired by trade costs his original 2025 round.
A38: Two keepers with the same cost: the higher-ranked player moves up one round, the other keeps that round. Two 1st rounders cost a 1st and a 2nd. "Higher-ranked" is resolved here by league-adjusted ADP (lower ADP = higher rank).
A39: Draft capital: 16 picks max, less picks traded away, plus picks acquired, less keepers selected. Minimum 14 picks if you keep two.
A40: {="Rounds traded away: "&_xlfn.LET(_xlpm.sl,MATCH(TRUE,EXACT('Draft Order-Traded Picks'!$B$2:$K$2,$M$13),0),_xlpm.g,INDEX('Draft Order-Traded Picks'!$B$3:$K$18,_xlfn.SEQUENCE(16),_xlpm.sl),IF(SUMPRODUCT(--(_xlpm.g<>""))=0,"none",_xlfn.TEXTJOIN(", ",TRUE,IF(_xlpm.g<>"","Rd "&_xlfn.SEQUENCE(16),""))))} -> Rounds traded away: none
A41: {="Rounds acquired: "&_xlfn.LET(_xlpm.m,MMULT(--EXACT('Draft Order-Traded Picks'!$B$3:$K$18,$M$12),_xlfn.SEQUENCE(10,1,1,0)),IF(SUM(_xlpm.m)=0,"none",_xlfn.TEXTJOIN(", ",TRUE,IF(_xlpm.m>0,"Rd "&_xlfn.SEQUENCE(16)&IF(_xlpm.m>1," (x"&_xlpm.m&")",""),""))&" - "&SUM(_xlpm.m)&" pick(s) total"))} -> Rounds acquired: none
A42: Value (Rd) = ADP Round minus Keeper Cost Round; positive = bargain. ADP is the 2026 full-PPR board adjusted for this league's 6-point passing TD (QBs move up 12 picks), a static snapshot taken July 2026. The roster table, team summary and position counts above are hard-coded values - they no longer recalculate. The keeper picker below is live and applies the keeper rules automatically; the traded-pick lines read from the 'Draft Order-Traded Picks' tab, so they update if more picks are traded.

Sheet Prestige Worldwide
A1: PRESTIGE WORLDWIDE ★ Ben
A2: 2025 Slot | B2: Player | C2: Pos | D2: NFL | E2: 2026 ADP (adj) | F2: ADP Round | G2: Keeper Cost (Rd) | H2: Value (Rd) | I2: Kept in 2025 | J2: How acquired | L2: TEAM SUMMARY
A3: Waiver add | B3: Dak Prescott | C3: QB | D3: DAL | E3: 53.8 | F3: 6 | G3: 8 | H3: 2 | J3: Waiver claim | L3: Players | M3: 18
A4: Waiver add | B4: Jordan Love | C4: QB | D4: GB | E4: 132.5 | F4: 14 | G4: 8 | H4: -6 | J4: Waiver claim | L4: Kept in 2025 (*) | M4: 2
A5: Round 10 | B5: De'Von Achane | C5: RB | D5: MIA | E5: 10.1 | F5: 2 | G5: 9 | H5: 7 | I5: * | J5: Drafted 2025 | L5: Avg ADP (league-adj) | M5: 74.18125
A6: Round 4 | B6: Breece Hall | C6: RB | D6: NYJ | E6: 28.9 | F6: 3 | G6: 4 | H6: 1 | J6: Drafted 2025 | L6: Best value (Rd) | M6: 7
A7: Round 1 | B7: Josh Jacobs | C7: RB | D7: GB | E7: 30 | F7: 3 | G7: 1 | H7: -2 | J7: Drafted 2025 | L7: Best value player | M7: Cam Skattebo
A8: Round 11 | B8: Cam Skattebo | C8: RB | D8: NYG | E8: 34.1 | F8: 4 | G8: 11 | H8: 7 | J8: Drafted 2025 | L8: Players with no ADP | M8: 2
A9: Round 6 | B9: Aaron Jones Sr. | C9: RB | D9: MIN | E9: 98.2 | F9: 10 | G9: 6 | H9: -4 | J9: Drafted 2025 | L9: Waiver adds (8th rd) | M9: 5
A10: Waiver add | B10: Kareem Hunt | C10: RB | D10: KC | G10: 8 | J10: Waiver claim
A11: Round 5 | B11: Tetairoa McMillan | C11: WR | D11: CAR | E11: 33.6 | F11: 4 | G11: 5 | H11: 1 | J11: Drafted 2025 | L11: Team key (do not edit) | M11: Prestige Worldwide (Ben)
A12: Round 2 | B12: Tee Higgins | C12: WR | D12: CIN | E12: 36.6 | F12: 4 | G12: 2 | H12: -2 | J12: Drafted 2025 | L12: Team name key | M12: Prestige Worldwide
A13: Waiver add | B13: DJ Moore | C13: WR | D13: BUF | E13: 50.7 | F13: 6 | G13: 8 | H13: 2 | J13: Waiver claim | L13: Draft header key | M13: Ben Prestige Worldwide
A14: Round 3 | B14: Mike Evans | C14: WR | D14: SF | E14: 54.9 | F14: 6 | G14: 2 | H14: -4 | I14: * | J14: Drafted 2025
A15: Round 8 | B15: Deebo Samuel Sr. | C15: WR | D15: SF | E15: 108.9 | F15: 11 | G15: 8 | H15: -3 | J15: Drafted 2025
A16: Waiver add | B16: Jerry Jeudy | C16: WR | D16: CLE | E16: 132.5 | F16: 14 | G16: 8 | H16: -6 | J16: Waiver claim
A17: Round 16 | B17: Dallas Goedert | C17: TE | D17: PHI | E17: 115.5 | F17: 12 | G17: 16 | H17: 4 | J17: Drafted 2025
A18: Round 7 | B18: Mark Andrews | C18: TE | D18: BAL | E18: 136.3 | F18: 14 | G18: 7 | H18: -7 | J18: Drafted 2025
A19: Round 12 | B19: Brandon Aubrey | C19: K | D19: DAL | E19: 130.3 | F19: 14 | G19: 12 | H19: -2 | J19: Drafted 2025
A20: Round 15 | B20: Bills | C20: DEF | D20: BUF | G20: 15 | J20: Drafted 2025
A21: POSITION COUNTS
A22: QB | B22: 2
A23: RB | B23: 6
A24: WR | B24: 6
A25: TE | B25: 2
A26: K | B26: 1
A27: DEF | B27: 1
A28: TOTAL | B28: =SUM(B22:B27) -> 18
A30: KEEPER PICKER - choose up to 2 (rules applied automatically)
A31: 2025 Slot | B31: Keeper (pick from list) | C31: Pos | D31: NFL | E31: ADP | F31: ADP Rd | G31: Base Cost (Rd) | H31: Adj Cost (Rd) | I31: Round Given Up | J31: Value (Rd)
A32: =IF($B32="","",IFERROR(_xlfn.XLOOKUP($B32,$B$3:$B$20,$A$3:$A$20),"")) | C32: =IF($B32="","",IFERROR(_xlfn.XLOOKUP($B32,$B$3:$B$20,$C$3:$C$20),"")) | D32: =IF($B32="","",IFERROR(_xlfn.XLOOKUP($B32,$B$3:$B$20,$D$3:$D$20),"")) | E32: =IF($B32="","",IFERROR(_xlfn.XLOOKUP($B32,$B$3:$B$20,$E$3:$E$20),"")) | F32: =IF($B32="","",IFERROR(_xlfn.XLOOKUP($B32,$B$3:$B$20,$F$3:$F$20),"")) | G32: =IF($B32="","",IFERROR(_xlfn.XLOOKUP($B32,$B$3:$B$20,$G$3:$G$20),"")) | H32: =IF($B32="","",IF(OR($B33="",$G32<>$G33),$G32,IF($G32=1,IF($E32<=$E33,1,2),IF($E32<=$E33,MAX(1,$G32-1),$G32)))) | I32: =IF($H32="","","Round "&$H32) | J32: =IF(OR($B32="",$F32=""),"",$F32-$H32)
A33: =IF($B33="","",IFERROR(_xlfn.XLOOKUP($B33,$B$3:$B$20,$A$3:$A$20),"")) | C33: =IF($B33="","",IFERROR(_xlfn.XLOOKUP($B33,$B$3:$B$20,$C$3:$C$20),"")) | D33: =IF($B33="","",IFERROR(_xlfn.XLOOKUP($B33,$B$3:$B$20,$D$3:$D$20),"")) | E33: =IF($B33="","",IFERROR(_xlfn.XLOOKUP($B33,$B$3:$B$20,$E$3:$E$20),"")) | F33: =IF($B33="","",IFERROR(_xlfn.XLOOKUP($B33,$B$3:$B$20,$F$3:$F$20),"")) | G33: =IF($B33="","",IFERROR(_xlfn.XLOOKUP($B33,$B$3:$B$20,$G$3:$G$20),"")) | H33: =IF($B33="","",IF(OR($B32="",$G33<>$G32),$G33,IF($G33=1,IF($E33<=$E32,1,2),IF($E33<=$E32,MAX(1,$G33-1),$G33)))) | I33: =IF($H33="","","Round "&$H33) | J33: =IF(OR($B33="",$F33=""),"",$F33-$H33)
A34: TOTALS | G34: =IF(COUNT($G$32:$G$33)=0,"",SUM($G$32:$G$33)) | H34: =IF(COUNT($H$32:$H$33)=0,"",SUM($H$32:$H$33)) | J34: =IF(COUNT($J$32:$J$33)=0,"",SUM($J$32:$J$33))
A36: RULES & SOURCES APPLIED ON THIS TAB
A37: Keeper cost = the round the player was drafted in 2025. A player kept in 2025 costs one round earlier. A player claimed off waivers costs an 8th (unless you originally drafted him). A keeper acquired by trade costs his original 2025 round.
A38: Two keepers with the same cost: the higher-ranked player moves up one round, the other keeps that round. Two 1st rounders cost a 1st and a 2nd. "Higher-ranked" is resolved here by league-adjusted ADP (lower ADP = higher rank).
A39: Draft capital: 16 picks max, less picks traded away, plus picks acquired, less keepers selected. Minimum 14 picks if you keep two.
A40: {="Rounds traded away: "&_xlfn.LET(_xlpm.sl,MATCH(TRUE,EXACT('Draft Order-Traded Picks'!$B$2:$K$2,$M$13),0),_xlpm.g,INDEX('Draft Order-Traded Picks'!$B$3:$K$18,_xlfn.SEQUENCE(16),_xlpm.sl),IF(SUMPRODUCT(--(_xlpm.g<>""))=0,"none",_xlfn.TEXTJOIN(", ",TRUE,IF(_xlpm.g<>"","Rd "&_xlfn.SEQUENCE(16),""))))} -> Rounds traded away: none
A41: {="Rounds acquired: "&_xlfn.LET(_xlpm.m,MMULT(--EXACT('Draft Order-Traded Picks'!$B$3:$K$18,$M$12),_xlfn.SEQUENCE(10,1,1,0)),IF(SUM(_xlpm.m)=0,"none",_xlfn.TEXTJOIN(", ",TRUE,IF(_xlpm.m>0,"Rd "&_xlfn.SEQUENCE(16)&IF(_xlpm.m>1," (x"&_xlpm.m&")",""),""))&" - "&SUM(_xlpm.m)&" pick(s) total"))} -> Rounds acquired: none
A42: Value (Rd) = ADP Round minus Keeper Cost Round; positive = bargain. ADP is the 2026 full-PPR board adjusted for this league's 6-point passing TD (QBs move up 12 picks), a static snapshot taken July 2026. The roster table, team summary and position counts above are hard-coded values - they no longer recalculate. The keeper picker below is live and applies the keeper rules automatically; the traded-pick lines read from the 'Draft Order-Traded Picks' tab, so they update if more picks are traded.

Sheet Colin for the win
A1: COLIN FOR THE WIN ★ Chris
A2: 2025 Slot | B2: Player | C2: Pos | D2: NFL | E2: 2026 ADP (adj) | F2: ADP Round | G2: Keeper Cost (Rd) | H2: Value (Rd) | I2: Kept in 2025 | J2: How acquired | L2: TEAM SUMMARY
A3: Round 9 | B3: Drake Maye | C3: QB | D3: NE | E3: 38.2 | F3: 4 | G3: 9 | H3: 5 | J3: Drafted 2025 | L3: Players | M3: 17
A4: Waiver add | B4: Bo Nix | C4: QB | D4: DEN | E4: 106.1 | F4: 11 | G4: 8 | H4: -3 | J4: Waiver claim | L4: Kept in 2025 (*) | M4: 2
A5: Round 3 | B5: James Cook III | C5: RB | D5: BUF | E5: 13.1 | F5: 2 | G5: 3 | H5: 1 | J5: Drafted 2025 | L5: Avg ADP (league-adj) | M5: 68.023077
A6: Round 1 | B6: Derrick Henry | C6: RB | D6: BAL | E6: 17.1 | F6: 2 | G6: 1 | H6: -1 | J6: Drafted 2025 | L6: Best value (Rd) | M6: 5
A7: Round 5 | B7: Tony Pollard | C7: RB | D7: TEN | E7: 67.3 | F7: 7 | G7: 5 | H7: -2 | J7: Drafted 2025 | L7: Best value player | M7: Drake Maye
A8: Round 8 | B8: Jordan Mason | C8: RB | D8: MIN | E8: 123.6 | F8: 13 | G8: 8 | H8: -5 | J8: Drafted 2025 | L8: Players with no ADP | M8: 4
A9: Round 2 | B9: A.J. Brown | C9: WR | D9: NE | E9: 17.5 | F9: 2 | G9: 2 | H9: 0 | J9: Drafted 2025 | L9: Waiver adds (8th rd) | M9: 4
A10: Round 4 | B10: Zay Flowers | C10: WR | D10: BAL | E10: 24.9 | F10: 3 | G10: 4 | H10: 1 | J10: Drafted 2025
A11: Round 10 | B11: Jameson Williams | C11: WR | D11: DET | E11: 44 | F11: 5 | G11: 9 | H11: 4 | I11: * | J11: Drafted 2025 | L11: Team key (do not edit) | M11: Colin for the win (Chris)
A12: Round 11 | B12: Josh Downs | C12: WR | D12: IND | E12: 84.3 | F12: 9 | G12: 11 | H12: 2 | J12: Drafted 2025 | L12: Team name key | M12: Colin for the win
A13: Round 6 | B13: Jordan Addison | C13: WR | D13: MIN | E13: 100.5 | F13: 11 | G13: 5 | H13: -6 | I13: * | J13: Drafted 2025 | L13: Draft header key | M13: Chris Colin for the win
A14: Waiver add | B14: Kayshon Boutte | C14: WR | D14: NE | G14: 8 | J14: Waiver claim
A15: Round 7 | B15: Tucker Kraft | C15: TE | D15: GB | E15: 104 | F15: 11 | G15: 7 | H15: -4 | J15: Drafted 2025
A16: Waiver add | B16: Cade Otton | C16: TE | D16: TB | G16: 8 | J16: Waiver claim
A17: Round 12 | B17: Hunter Henry | C17: TE | D17: NE | G17: 12 | J17: Drafted 2025
A18: Round 14 | B18: Cameron Dicker | C18: K | D18: LAC | E18: 143.7 | F18: 15 | G18: 14 | H18: -1 | J18: Drafted 2025
A19: Waiver add | B19: Buccaneers | C19: DEF | D19: TB | G19: 8 | J19: Waiver claim
A21: POSITION COUNTS
A22: QB | B22: 2
A23: RB | B23: 4
A24: WR | B24: 6
A25: TE | B25: 3
A26: K | B26: 1
A27: DEF | B27: 1
A28: TOTAL | B28: =SUM(B22:B27) -> 17
A30: KEEPER PICKER - choose up to 2 (rules applied automatically)
A31: 2025 Slot | B31: Keeper (pick from list) | C31: Pos | D31: NFL | E31: ADP | F31: ADP Rd | G31: Base Cost (Rd) | H31: Adj Cost (Rd) | I31: Round Given Up | J31: Value (Rd)
A32: =IF($B32="","",IFERROR(_xlfn.XLOOKUP($B32,$B$3:$B$20,$A$3:$A$20),"")) | C32: =IF($B32="","",IFERROR(_xlfn.XLOOKUP($B32,$B$3:$B$20,$C$3:$C$20),"")) | D32: =IF($B32="","",IFERROR(_xlfn.XLOOKUP($B32,$B$3:$B$20,$D$3:$D$20),"")) | E32: =IF($B32="","",IFERROR(_xlfn.XLOOKUP($B32,$B$3:$B$20,$E$3:$E$20),"")) | F32: =IF($B32="","",IFERROR(_xlfn.XLOOKUP($B32,$B$3:$B$20,$F$3:$F$20),"")) | G32: =IF($B32="","",IFERROR(_xlfn.XLOOKUP($B32,$B$3:$B$20,$G$3:$G$20),"")) | H32: =IF($B32="","",IF(OR($B33="",$G32<>$G33),$G32,IF($G32=1,IF($E32<=$E33,1,2),IF($E32<=$E33,MAX(1,$G32-1),$G32)))) | I32: =IF($H32="","","Round "&$H32) | J32: =IF(OR($B32="",$F32=""),"",$F32-$H32)
A33: =IF($B33="","",IFERROR(_xlfn.XLOOKUP($B33,$B$3:$B$20,$A$3:$A$20),"")) | C33: =IF($B33="","",IFERROR(_xlfn.XLOOKUP($B33,$B$3:$B$20,$C$3:$C$20),"")) | D33: =IF($B33="","",IFERROR(_xlfn.XLOOKUP($B33,$B$3:$B$20,$D$3:$D$20),"")) | E33: =IF($B33="","",IFERROR(_xlfn.XLOOKUP($B33,$B$3:$B$20,$E$3:$E$20),"")) | F33: =IF($B33="","",IFERROR(_xlfn.XLOOKUP($B33,$B$3:$B$20,$F$3:$F$20),"")) | G33: =IF($B33="","",IFERROR(_xlfn.XLOOKUP($B33,$B$3:$B$20,$G$3:$G$20),"")) | H33: =IF($B33="","",IF(OR($B32="",$G33<>$G32),$G33,IF($G33=1,IF($E33<=$E32,1,2),IF($E33<=$E32,MAX(1,$G33-1),$G33)))) | I33: =IF($H33="","","Round "&$H33) | J33: =IF(OR($B33="",$F33=""),"",$F33-$H33)
A34: TOTALS | G34: =IF(COUNT($G$32:$G$33)=0,"",SUM($G$32:$G$33)) | H34: =IF(COUNT($H$32:$H$33)=0,"",SUM($H$32:$H$33)) | J34: =IF(COUNT($J$32:$J$33)=0,"",SUM($J$32:$J$33))
A36: RULES & SOURCES APPLIED ON THIS TAB
A37: Keeper cost = the round the player was drafted in 2025. A player kept in 2025 costs one round earlier. A player claimed off waivers costs an 8th (unless you originally drafted him). A keeper acquired by trade costs his original 2025 round.
A38: Two keepers with the same cost: the higher-ranked player moves up one round, the other keeps that round. Two 1st rounders cost a 1st and a 2nd. "Higher-ranked" is resolved here by league-adjusted ADP (lower ADP = higher rank).
A39: Draft capital: 16 picks max, less picks traded away, plus picks acquired, less keepers selected. Minimum 14 picks if you keep two.
A40: {="Rounds traded away: "&_xlfn.LET(_xlpm.sl,MATCH(TRUE,EXACT('Draft Order-Traded Picks'!$B$2:$K$2,$M$13),0),_xlpm.g,INDEX('Draft Order-Traded Picks'!$B$3:$K$18,_xlfn.SEQUENCE(16),_xlpm.sl),IF(SUMPRODUCT(--(_xlpm.g<>""))=0,"none",_xlfn.TEXTJOIN(", ",TRUE,IF(_xlpm.g<>"","Rd "&_xlfn.SEQUENCE(16),""))))} -> Rounds traded away: none
A41: {="Rounds acquired: "&_xlfn.LET(_xlpm.m,MMULT(--EXACT('Draft Order-Traded Picks'!$B$3:$K$18,$M$12),_xlfn.SEQUENCE(10,1,1,0)),IF(SUM(_xlpm.m)=0,"none",_xlfn.TEXTJOIN(", ",TRUE,IF(_xlpm.m>0,"Rd "&_xlfn.SEQUENCE(16)&IF(_xlpm.m>1," (x"&_xlpm.m&")",""),""))&" - "&SUM(_xlpm.m)&" pick(s) total"))} -> Rounds acquired: none
A42: Value (Rd) = ADP Round minus Keeper Cost Round; positive = bargain. ADP is the 2026 full-PPR board adjusted for this league's 6-point passing TD (QBs move up 12 picks), a static snapshot taken July 2026. The roster table, team summary and position counts above are hard-coded values - they no longer recalculate. The keeper picker below is live and applies the keeper rules automatically; the traded-pick lines read from the 'Draft Order-Traded Picks' tab, so they update if more picks are traded.

Sheet The V&G Express
A1: THE V&G EXPRESS ★ Kevin
A2: 2025 Slot | B2: Player | C2: Pos | D2: NFL | E2: 2026 ADP (adj) | F2: ADP Round | G2: Keeper Cost (Rd) | H2: Value (Rd) | I2: Kept in 2025 | J2: How acquired | L2: TEAM SUMMARY
A3: Waiver add | B3: Joe Burrow | C3: QB | D3: CIN | E3: 44 | F3: 5 | G3: 8 | H3: 3 | J3: Waiver claim | L3: Players | M3: 16
A4: Waiver add | B4: Jacoby Brissett | C4: QB | D4: ARI | G4: 8 | J4: Waiver claim | L4: Kept in 2025 (*) | M4: 1
A5: Round 7 | B5: Kyren Williams | C5: RB | D5: LAR | E5: 32.4 | F5: 4 | G5: 6 | H5: 2 | I5: * | J5: Drafted 2025 | L5: Avg ADP (league-adj) | M5: 59.8
A6: Round 3 | B6: TreVeyon Henderson | C6: RB | D6: NE | E6: 59.1 | F6: 6 | G6: 3 | H6: -3 | J6: Drafted 2025 | L6: Best value (Rd) | M6: 3
A7: Waiver add | B7: Rico Dowdle | C7: RB | D7: PIT | E7: 74.1 | F7: 8 | G7: 8 | H7: 0 | J7: Waiver claim | L7: Best value player | M7: Joe Burrow
A8: Waiver add | B8: Blake Corum | C8: RB | D8: LAR | E8: 122.6 | F8: 13 | G8: 8 | H8: -5 | J8: Waiver claim | L8: Players with no ADP | M8: 4
A9: Waiver add | B9: Devin Neal | C9: RB | D9: NO | G9: 8 | J9: Waiver claim | L9: Waiver adds (8th rd) | M9: 9
A10: Round 1 | B10: Drake London | C10: WR | D10: ATL | E10: 10.3 | F10: 2 | G10: 1 | H10: -1 | J10: Drafted 2025
A11: Round 4 | B11: George Pickens | C11: WR | D11: DAL | E11: 19.9 | F11: 2 | G11: 4 | H11: 2 | J11: Drafted 2025 | L11: Team key (do not edit) | M11: The V&G Express (Kevin)
A12: Round 6 | B12: Emeka Egbuka | C12: WR | D12: TB | E12: 37 | F12: 4 | G12: 6 | H12: 2 | J12: Drafted 2025 | L12: Team name key | M12: The V&G Express
A13: Round 5 | B13: Courtland Sutton | C13: WR | D13: DEN | E13: 60.4 | F13: 7 | G13: 5 | H13: -2 | J13: Drafted 2025 | L13: Draft header key | M13: Kevin The V&G Express
A14: Waiver add | B14: Christian Watson | C14: WR | D14: GB | E14: 63.5 | F14: 7 | G14: 8 | H14: 1 | J14: Waiver claim
A15: Waiver add | B15: Jayden Higgins | C15: WR | D15: HOU | E15: 129.6 | F15: 13 | G15: 8 | H15: -5 | J15: Waiver claim
A16: Round 10 | B16: Tyler Warren | C16: TE | D16: IND | E16: 64.7 | F16: 7 | G16: 10 | H16: 3 | J16: Drafted 2025
A17: Waiver add | B17: Evan McPherson | C17: K | D17: CIN | G17: 8 | J17: Waiver claim
A18: Waiver add | B18: Rams | C18: DEF | D18: LAR | G18: 8 | J18: Waiver claim
A21: POSITION COUNTS
A22: QB | B22: 2
A23: RB | B23: 5
A24: WR | B24: 6
A25: TE | B25: 1
A26: K | B26: 1
A27: DEF | B27: 1
A28: TOTAL | B28: =SUM(B22:B27) -> 16
A30: KEEPER PICKER - choose up to 2 (rules applied automatically)
A31: 2025 Slot | B31: Keeper (pick from list) | C31: Pos | D31: NFL | E31: ADP | F31: ADP Rd | G31: Base Cost (Rd) | H31: Adj Cost (Rd) | I31: Round Given Up | J31: Value (Rd)
A32: =IF($B32="","",IFERROR(_xlfn.XLOOKUP($B32,$B$3:$B$20,$A$3:$A$20),"")) | C32: =IF($B32="","",IFERROR(_xlfn.XLOOKUP($B32,$B$3:$B$20,$C$3:$C$20),"")) | D32: =IF($B32="","",IFERROR(_xlfn.XLOOKUP($B32,$B$3:$B$20,$D$3:$D$20),"")) | E32: =IF($B32="","",IFERROR(_xlfn.XLOOKUP($B32,$B$3:$B$20,$E$3:$E$20),"")) | F32: =IF($B32="","",IFERROR(_xlfn.XLOOKUP($B32,$B$3:$B$20,$F$3:$F$20),"")) | G32: =IF($B32="","",IFERROR(_xlfn.XLOOKUP($B32,$B$3:$B$20,$G$3:$G$20),"")) | H32: =IF($B32="","",IF(OR($B33="",$G32<>$G33),$G32,IF($G32=1,IF($E32<=$E33,1,2),IF($E32<=$E33,MAX(1,$G32-1),$G32)))) | I32: =IF($H32="","","Round "&$H32) | J32: =IF(OR($B32="",$F32=""),"",$F32-$H32)
A33: =IF($B33="","",IFERROR(_xlfn.XLOOKUP($B33,$B$3:$B$20,$A$3:$A$20),"")) | C33: =IF($B33="","",IFERROR(_xlfn.XLOOKUP($B33,$B$3:$B$20,$C$3:$C$20),"")) | D33: =IF($B33="","",IFERROR(_xlfn.XLOOKUP($B33,$B$3:$B$20,$D$3:$D$20),"")) | E33: =IF($B33="","",IFERROR(_xlfn.XLOOKUP($B33,$B$3:$B$20,$E$3:$E$20),"")) | F33: =IF($B33="","",IFERROR(_xlfn.XLOOKUP($B33,$B$3:$B$20,$F$3:$F$20),"")) | G33: =IF($B33="","",IFERROR(_xlfn.XLOOKUP($B33,$B$3:$B$20,$G$3:$G$20),"")) | H33: =IF($B33="","",IF(OR($B32="",$G33<>$G32),$G33,IF($G33=1,IF($E33<=$E32,1,2),IF($E33<=$E32,MAX(1,$G33-1),$G33)))) | I33: =IF($H33="","","Round "&$H33) | J33: =IF(OR($B33="",$F33=""),"",$F33-$H33)
A34: TOTALS | G34: =IF(COUNT($G$32:$G$33)=0,"",SUM($G$32:$G$33)) | H34: =IF(COUNT($H$32:$H$33)=0,"",SUM($H$32:$H$33)) | J34: =IF(COUNT($J$32:$J$33)=0,"",SUM($J$32:$J$33))
A36: RULES & SOURCES APPLIED ON THIS TAB
A37: Keeper cost = the round the player was drafted in 2025. A player kept in 2025 costs one round earlier. A player claimed off waivers costs an 8th (unless you originally drafted him). A keeper acquired by trade costs his original 2025 round.
A38: Two keepers with the same cost: the higher-ranked player moves up one round, the other keeps that round. Two 1st rounders cost a 1st and a 2nd. "Higher-ranked" is resolved here by league-adjusted ADP (lower ADP = higher rank).
A39: Draft capital: 16 picks max, less picks traded away, plus picks acquired, less keepers selected. Minimum 14 picks if you keep two.
A40: {="Rounds traded away: "&_xlfn.LET(_xlpm.sl,MATCH(TRUE,EXACT('Draft Order-Traded Picks'!$B$2:$K$2,$M$13),0),_xlpm.g,INDEX('Draft Order-Traded Picks'!$B$3:$K$18,_xlfn.SEQUENCE(16),_xlpm.sl),IF(SUMPRODUCT(--(_xlpm.g<>""))=0,"none",_xlfn.TEXTJOIN(", ",TRUE,IF(_xlpm.g<>"","Rd "&_xlfn.SEQUENCE(16),""))))} -> Rounds traded away: none
A41: {="Rounds acquired: "&_xlfn.LET(_xlpm.m,MMULT(--EXACT('Draft Order-Traded Picks'!$B$3:$K$18,$M$12),_xlfn.SEQUENCE(10,1,1,0)),IF(SUM(_xlpm.m)=0,"none",_xlfn.TEXTJOIN(", ",TRUE,IF(_xlpm.m>0,"Rd "&_xlfn.SEQUENCE(16)&IF(_xlpm.m>1," (x"&_xlpm.m&")",""),""))&" - "&SUM(_xlpm.m)&" pick(s) total"))} -> Rounds acquired: none
A42: Value (Rd) = ADP Round minus Keeper Cost Round; positive = bargain. ADP is the 2026 full-PPR board adjusted for this league's 6-point passing TD (QBs move up 12 picks), a static snapshot taken July 2026. The roster table, team summary and position counts above are hard-coded values - they no longer recalculate. The keeper picker below is live and applies the keeper rules automatically; the traded-pick lines read from the 'Draft Order-Traded Picks' tab, so they update if more picks are traded.

Sheet Maye I put it in your Boutte
A1: MAYE I PUT IT IN YOUR BOUTTE? ★ Nate
A2: 2025 Slot | B2: Player | C2: Pos | D2: NFL | E2: 2026 ADP (adj) | F2: ADP Round | G2: Keeper Cost (Rd) | H2: Value (Rd) | I2: Kept in 2025 | J2: How acquired | L2: TEAM SUMMARY
A3: Waiver add | B3: Brock Purdy | C3: QB | D3: SF | E3: 75.5 | F3: 8 | G3: 8 | H3: 0 | J3: Waiver claim | L3: Players | M3: 18
A4: Round 11 | B4: Baker Mayfield | C4: QB | D4: TB | E4: 117.8 | F4: 12 | G4: 11 | H4: -1 | J4: Drafted 2025 | L4: Kept in 2025 (*) | M4: 2
A5: Round 1 | B5: Saquon Barkley | C5: RB | D5: PHI | E5: 20.1 | F5: 3 | G5: 1 | H5: -2 | I5: * | J5: Drafted 2025 | L5: Avg ADP (league-adj) | M5: 83.738462
A6: Round 12 | B6: Javonte Williams | C6: RB | D6: DAL | E6: 37.4 | F6: 4 | G6: 12 | H6: 8 | J6: Drafted 2025 | L6: Best value (Rd) | M6: 8
A7: Round 4 | B7: RJ Harvey | C7: RB | D7: DEN | E7: 83.4 | F7: 9 | G7: 4 | H7: -5 | J7: Drafted 2025 | L7: Best value player | M7: Javonte Williams
A8: Round 8 | B8: J.K. Dobbins | C8: RB | D8: DEN | E8: 96.6 | F8: 10 | G8: 8 | H8: -2 | J8: Drafted 2025 | L8: Players with no ADP | M8: 5
A9: Round 3 | B9: Ja'Marr Chase | C9: WR | D9: CIN | E9: 3.9 | F9: 1 | G9: 2 | H9: 1 | I9: * | J9: Drafted 2025 | L9: Waiver adds (8th rd) | M9: 7
A10: Waiver add | B10: Parker Washington | C10: WR | D10: JAX | E10: 67.1 | F10: 7 | G10: 8 | H10: 1 | J10: Waiver claim
A11: Waiver add | B11: Michael Wilson | C11: WR | D11: ARI | E11: 81.5 | F11: 9 | G11: 8 | H11: -1 | J11: Waiver claim | L11: Team key (do not edit) | M11: Maye I put it in your Boutte? (Nate)
A12: Round 5 | B12: Ricky Pearsall | C12: WR | D12: SF | E12: 110.9 | F12: 12 | G12: 5 | H12: -7 | J12: Drafted 2025 | L12: Team name key | M12: Maye I put it in your Boutte?
A13: Round 9 | B13: Jauan Jennings | C13: WR | D13: MIN | E13: 144.8 | F13: 15 | G13: 9 | H13: -6 | J13: Drafted 2025 | L13: Draft header key | M13: Nate Maye I put it in your Boutte?
A14: Waiver add | B14: Devaughn Vele | C14: WR | D14: NO | G14: 8 | J14: Waiver claim
A15: Round 6 | B15: Travis Hunter | C15: WR | D15: JAX | G15: 6 | J15: Drafted 2025
A16: Round 2 | B16: George Kittle | C16: TE | D16: SF | E16: 114.8 | F16: 12 | G16: 2 | H16: -10 | J16: Drafted 2025
A17: Round 14 | B17: Jake Ferguson | C17: TE | D17: DAL | E17: 134.8 | F17: 14 | G17: 14 | H17: 0 | J17: Drafted 2025
A18: Waiver add | B18: Will Reichard | C18: K | D18: MIN | G18: 8 | J18: Waiver claim
A19: Waiver add | B19: Eagles | C19: DEF | D19: PHI | G19: 8 | J19: Waiver claim
A20: Waiver add | B20: Patriots | C20: DEF | D20: NE | G20: 8 | J20: Waiver claim
A21: POSITION COUNTS
A22: QB | B22: 2
A23: RB | B23: 4
A24: WR | B24: 7
A25: TE | B25: 2
A26: K | B26: 1
A27: DEF | B27: 2
A28: TOTAL | B28: =SUM(B22:B27) -> 18
A30: KEEPER PICKER - choose up to 2 (rules applied automatically)
A31: 2025 Slot | B31: Keeper (pick from list) | C31: Pos | D31: NFL | E31: ADP | F31: ADP Rd | G31: Base Cost (Rd) | H31: Adj Cost (Rd) | I31: Round Given Up | J31: Value (Rd)
A32: =IF($B32="","",IFERROR(_xlfn.XLOOKUP($B32,$B$3:$B$20,$A$3:$A$20),"")) | C32: =IF($B32="","",IFERROR(_xlfn.XLOOKUP($B32,$B$3:$B$20,$C$3:$C$20),"")) | D32: =IF($B32="","",IFERROR(_xlfn.XLOOKUP($B32,$B$3:$B$20,$D$3:$D$20),"")) | E32: =IF($B32="","",IFERROR(_xlfn.XLOOKUP($B32,$B$3:$B$20,$E$3:$E$20),"")) | F32: =IF($B32="","",IFERROR(_xlfn.XLOOKUP($B32,$B$3:$B$20,$F$3:$F$20),"")) | G32: =IF($B32="","",IFERROR(_xlfn.XLOOKUP($B32,$B$3:$B$20,$G$3:$G$20),"")) | H32: =IF($B32="","",IF(OR($B33="",$G32<>$G33),$G32,IF($G32=1,IF($E32<=$E33,1,2),IF($E32<=$E33,MAX(1,$G32-1),$G32)))) | I32: =IF($H32="","","Round "&$H32) | J32: =IF(OR($B32="",$F32=""),"",$F32-$H32)
A33: =IF($B33="","",IFERROR(_xlfn.XLOOKUP($B33,$B$3:$B$20,$A$3:$A$20),"")) | C33: =IF($B33="","",IFERROR(_xlfn.XLOOKUP($B33,$B$3:$B$20,$C$3:$C$20),"")) | D33: =IF($B33="","",IFERROR(_xlfn.XLOOKUP($B33,$B$3:$B$20,$D$3:$D$20),"")) | E33: =IF($B33="","",IFERROR(_xlfn.XLOOKUP($B33,$B$3:$B$20,$E$3:$E$20),"")) | F33: =IF($B33="","",IFERROR(_xlfn.XLOOKUP($B33,$B$3:$B$20,$F$3:$F$20),"")) | G33: =IF($B33="","",IFERROR(_xlfn.XLOOKUP($B33,$B$3:$B$20,$G$3:$G$20),"")) | H33: =IF($B33="","",IF(OR($B32="",$G33<>$G32),$G33,IF($G33=1,IF($E33<=$E32,1,2),IF($E33<=$E32,MAX(1,$G33-1),$G33)))) | I33: =IF($H33="","","Round "&$H33) | J33: =IF(OR($B33="",$F33=""),"",$F33-$H33)
A34: TOTALS | G34: =IF(COUNT($G$32:$G$33)=0,"",SUM($G$32:$G$33)) | H34: =IF(COUNT($H$32:$H$33)=0,"",SUM($H$32:$H$33)) | J34: =IF(COUNT($J$32:$J$33)=0,"",SUM($J$32:$J$33))
A36: RULES & SOURCES APPLIED ON THIS TAB
A37: Keeper cost = the round the player was drafted in 2025. A player kept in 2025 costs one round earlier. A player claimed off waivers costs an 8th (unless you originally drafted him). A keeper acquired by trade costs his original 2025 round.
A38: Two keepers with the same cost: the higher-ranked player moves up one round, the other keeps that round. Two 1st rounders cost a 1st and a 2nd. "Higher-ranked" is resolved here by league-adjusted ADP (lower ADP = higher rank).
A39: Draft capital: 16 picks max, less picks traded away, plus picks acquired, less keepers selected. Minimum 14 picks if you keep two.
A40: {="Rounds traded away: "&_xlfn.LET(_xlpm.sl,MATCH(TRUE,EXACT('Draft Order-Traded Picks'!$B$2:$K$2,$M$13),0),_xlpm.g,INDEX('Draft Order-Traded Picks'!$B$3:$K$18,_xlfn.SEQUENCE(16),_xlpm.sl),IF(SUMPRODUCT(--(_xlpm.g<>""))=0,"none",_xlfn.TEXTJOIN(", ",TRUE,IF(_xlpm.g<>"","Rd "&_xlfn.SEQUENCE(16),""))))} -> Rounds traded away: none
A41: {="Rounds acquired: "&_xlfn.LET(_xlpm.m,MMULT(--EXACT('Draft Order-Traded Picks'!$B$3:$K$18,$M$12),_xlfn.SEQUENCE(10,1,1,0)),IF(SUM(_xlpm.m)=0,"none",_xlfn.TEXTJOIN(", ",TRUE,IF(_xlpm.m>0,"Rd "&_xlfn.SEQUENCE(16)&IF(_xlpm.m>1," (x"&_xlpm.m&")",""),""))&" - "&SUM(_xlpm.m)&" pick(s) total"))} -> Rounds acquired: none
A42: Value (Rd) = ADP Round minus Keeper Cost Round; positive = bargain. ADP is the 2026 full-PPR board adjusted for this league's 6-point passing TD (QBs move up 12 picks), a static snapshot taken July 2026. The roster table, team summary and position counts above are hard-coded values - they no longer recalculate. The keeper picker below is live and applies the keeper rules automatically; the traded-pick lines read from the 'Draft Order-Traded Picks' tab, so they update if more picks are traded.

Sheet Leeroy Judkins
A1: LEEROY JUDKINS ★ JR
A2: 2025 Slot | B2: Player | C2: Pos | D2: NFL | E2: 2026 ADP (adj) | F2: ADP Round | G2: Keeper Cost (Rd) | H2: Value (Rd) | I2: Kept in 2025 | J2: How acquired | L2: TEAM SUMMARY
A3: Round 11 | B3: Josh Allen | C3: QB | D3: BUF | E3: 18.6 | F3: 2 | G3: 10 | H3: 8 | I3: * | J3: Drafted 2025 | L3: Players | M3: 18
A4: Round 1 | B4: Ashton Jeanty | C4: RB | D4: LV | E4: 14.9 | F4: 2 | G4: 1 | H4: -1 | J4: Drafted 2025 | L4: Kept in 2025 (*) | M4: 2
A5: Round 3 | B5: Omarion Hampton | C5: RB | D5: LAC | E5: 20.7 | F5: 3 | G5: 3 | H5: 0 | J5: Acquired by trade | L5: Avg ADP (league-adj) | M5: 49.408333
A6: Round 10 | B6: Quinshon Judkins | C6: RB | D6: CLE | E6: 51.4 | F6: 6 | G6: 10 | H6: 4 | J6: Drafted 2025 | L6: Best value (Rd) | M6: 8
A7: Waiver add | B7: Bhayshul Tuten | C7: RB | D7: JAX | E7: 54.2 | F7: 6 | G7: 8 | H7: 2 | J7: Waiver claim | L7: Best value player | M7: Josh Allen
A8: Round 8 | B8: Braelon Allen | C8: RB | D8: NYJ | E8: 149.7 | F8: 15 | G8: 8 | H8: -7 | J8: Drafted 2025 | L8: Players with no ADP | M8: 6
A9: Waiver add | B9: Kaleb Johnson | C9: RB | D9: PIT | G9: 8 | J9: Waiver claim | L9: Waiver adds (8th rd) | M9: 8
A10: Waiver add | B10: Trey Benson | C10: RB | D10: ARI | G10: 8 | J10: Waiver claim
A11: Waiver add | B11: Tyler Allgeier | C11: RB | D11: ARI | G11: 8 | J11: Waiver claim | L11: Team key (do not edit) | M11: Leeroy Judkins (JR)
A12: Round 1 | B12: CeeDee Lamb | C12: WR | D12: DAL | E12: 10.8 | F12: 2 | G12: 1 | H12: -1 | J12: Acquired by trade | L12: Team name key | M12: Leeroy Judkins
A13: Round 9 | B13: Nico Collins | C13: WR | D13: HOU | E13: 22.2 | F13: 3 | G13: 8 | H13: 5 | I13: * | J13: Drafted 2025 | L13: Draft header key | M13: JR Leeroy Judkins
A14: Round 6 | B14: Jaylen Waddle | C14: WR | D14: DEN | E14: 46.1 | F14: 5 | G14: 6 | H14: 1 | J14: Drafted 2025
A15: Round 7 | B15: Stefon Diggs | C15: WR | D15: WAS | E15: 93.5 | F15: 10 | G15: 7 | H15: -3 | J15: Drafted 2025
A16: Waiver add | B16: Isaac TeSlaa | C16: WR | D16: DET | G16: 8 | J16: Waiver claim
A17: Waiver add | B17: Kyle Williams | C17: WR | D17: NE | G17: 8 | J17: Waiver claim
A18: Round 2 | B18: Trey McBride | C18: TE | D18: ARI | E18: 31.7 | F18: 4 | G18: 2 | H18: -2 | J18: Drafted 2025
A19: Waiver add | B19: Harold Fannin Jr. | C19: TE | D19: CLE | E19: 79.1 | F19: 8 | G19: 8 | H19: 0 | J19: Waiver claim
A20: Waiver add | B20: Oronde Gadsden | C20: TE | D20: LAC | G20: 8 | J20: Waiver claim
A21: POSITION COUNTS
A22: QB | B22: 1
A23: RB | B23: 8
A24: WR | B24: 6
A25: TE | B25: 3
A26: K | B26: 0
A27: DEF | B27: 0
A28: TOTAL | B28: =SUM(B22:B27) -> 18
A30: KEEPER PICKER - choose up to 2 (rules applied automatically)
A31: 2025 Slot | B31: Keeper (pick from list) | C31: Pos | D31: NFL | E31: ADP | F31: ADP Rd | G31: Base Cost (Rd) | H31: Adj Cost (Rd) | I31: Round Given Up | J31: Value (Rd)
A32: =IF($B32="","",IFERROR(_xlfn.XLOOKUP($B32,$B$3:$B$20,$A$3:$A$20),"")) | C32: =IF($B32="","",IFERROR(_xlfn.XLOOKUP($B32,$B$3:$B$20,$C$3:$C$20),"")) | D32: =IF($B32="","",IFERROR(_xlfn.XLOOKUP($B32,$B$3:$B$20,$D$3:$D$20),"")) | E32: =IF($B32="","",IFERROR(_xlfn.XLOOKUP($B32,$B$3:$B$20,$E$3:$E$20),"")) | F32: =IF($B32="","",IFERROR(_xlfn.XLOOKUP($B32,$B$3:$B$20,$F$3:$F$20),"")) | G32: =IF($B32="","",IFERROR(_xlfn.XLOOKUP($B32,$B$3:$B$20,$G$3:$G$20),"")) | H32: =IF($B32="","",IF(OR($B33="",$G32<>$G33),$G32,IF($G32=1,IF($E32<=$E33,1,2),IF($E32<=$E33,MAX(1,$G32-1),$G32)))) | I32: =IF($H32="","","Round "&$H32) | J32: =IF(OR($B32="",$F32=""),"",$F32-$H32)
A33: =IF($B33="","",IFERROR(_xlfn.XLOOKUP($B33,$B$3:$B$20,$A$3:$A$20),"")) | C33: =IF($B33="","",IFERROR(_xlfn.XLOOKUP($B33,$B$3:$B$20,$C$3:$C$20),"")) | D33: =IF($B33="","",IFERROR(_xlfn.XLOOKUP($B33,$B$3:$B$20,$D$3:$D$20),"")) | E33: =IF($B33="","",IFERROR(_xlfn.XLOOKUP($B33,$B$3:$B$20,$E$3:$E$20),"")) | F33: =IF($B33="","",IFERROR(_xlfn.XLOOKUP($B33,$B$3:$B$20,$F$3:$F$20),"")) | G33: =IF($B33="","",IFERROR(_xlfn.XLOOKUP($B33,$B$3:$B$20,$G$3:$G$20),"")) | H33: =IF($B33="","",IF(OR($B32="",$G33<>$G32),$G33,IF($G33=1,IF($E33<=$E32,1,2),IF($E33<=$E32,MAX(1,$G33-1),$G33)))) | I33: =IF($H33="","","Round "&$H33) | J33: =IF(OR($B33="",$F33=""),"",$F33-$H33)
A34: TOTALS | G34: =IF(COUNT($G$32:$G$33)=0,"",SUM($G$32:$G$33)) | H34: =IF(COUNT($H$32:$H$33)=0,"",SUM($H$32:$H$33)) | J34: =IF(COUNT($J$32:$J$33)=0,"",SUM($J$32:$J$33))
A36: RULES & SOURCES APPLIED ON THIS TAB
A37: Keeper cost = the round the player was drafted in 2025. A player kept in 2025 costs one round earlier. A player claimed off waivers costs an 8th (unless you originally drafted him). A keeper acquired by trade costs his original 2025 round.
A38: Two keepers with the same cost: the higher-ranked player moves up one round, the other keeps that round. Two 1st rounders cost a 1st and a 2nd. "Higher-ranked" is resolved here by league-adjusted ADP (lower ADP = higher rank).
A39: Draft capital: 16 picks max, less picks traded away, plus picks acquired, less keepers selected. Minimum 14 picks if you keep two.
A40: {="Rounds traded away: "&_xlfn.LET(_xlpm.sl,MATCH(TRUE,EXACT('Draft Order-Traded Picks'!$B$2:$K$2,$M$13),0),_xlpm.g,INDEX('Draft Order-Traded Picks'!$B$3:$K$18,_xlfn.SEQUENCE(16),_xlpm.sl),IF(SUMPRODUCT(--(_xlpm.g<>""))=0,"none",_xlfn.TEXTJOIN(", ",TRUE,IF(_xlpm.g<>"","Rd "&_xlfn.SEQUENCE(16),""))))} -> Rounds traded away: Rd 2, Rd 7
A41: {="Rounds acquired: "&_xlfn.LET(_xlpm.m,MMULT(--EXACT('Draft Order-Traded Picks'!$B$3:$K$18,$M$12),_xlfn.SEQUENCE(10,1,1,0)),IF(SUM(_xlpm.m)=0,"none",_xlfn.TEXTJOIN(", ",TRUE,IF(_xlpm.m>0,"Rd "&_xlfn.SEQUENCE(16)&IF(_xlpm.m>1," (x"&_xlpm.m&")",""),""))&" - "&SUM(_xlpm.m)&" pick(s) total"))} -> Rounds acquired: Rd 10, Rd 12 - 2 pick(s) total
A42: Value (Rd) = ADP Round minus Keeper Cost Round; positive = bargain. ADP is the 2026 full-PPR board adjusted for this league's 6-point passing TD (QBs move up 12 picks), a static snapshot taken July 2026. The roster table, team summary and position counts above are hard-coded values - they no longer recalculate. The keeper picker below is live and applies the keeper rules automatically; the traded-pick lines read from the 'Draft Order-Traded Picks' tab, so they update if more picks are traded.

Sheet Any given Sunday
A1: ANY GIVEN SUNDAY ★ Robert
A2: 2025 Slot | B2: Player | C2: Pos | D2: NFL | E2: 2026 ADP (adj) | F2: ADP Round | G2: Keeper Cost (Rd) | H2: Value (Rd) | I2: Kept in 2025 | J2: How acquired | L2: TEAM SUMMARY
A3: Round 2 | B3: Jalen Hurts | C3: QB | D3: PHI | E3: 67.2 | F3: 7 | G3: 2 | H3: -5 | J3: Drafted 2025 | L3: Players | M3: 16
A4: Waiver add | B4: Trevor Lawrence | C4: QB | D4: JAX | E4: 80.2 | F4: 9 | G4: 8 | H4: -1 | J4: Waiver claim | L4: Kept in 2025 (*) | M4: 2
A5: Round 2 | B5: Jonathan Taylor | C5: RB | D5: IND | E5: 7.5 | F5: 1 | G5: 2 | H5: 1 | J5: Drafted 2025 | L5: Avg ADP (league-adj) | M5: 64.573333
A6: Round 14 | B6: Bucky Irving | C6: RB | D6: TB | E6: 45.2 | F6: 5 | G6: 13 | H6: 8 | I6: * | J6: Drafted 2025 | L6: Best value (Rd) | M6: 8
A7: Round 5 | B7: David Montgomery | C7: RB | D7: HOU | E7: 61.1 | F7: 7 | G7: 5 | H7: -2 | J7: Drafted 2025 | L7: Best value player | M7: Bucky Irving
A8: Round 2 | B8: Puka Nacua | C8: WR | D8: LAR | E8: 3.1 | F8: 1 | G8: 2 | H8: 1 | J8: Acquired by trade | L8: Players with no ADP | M8: 1
A9: Round 1 | B9: Amon-Ra St. Brown | C9: WR | D9: DET | E9: 6.6 | F9: 1 | G9: 1 | H9: 0 | J9: Drafted 2025 | L9: Waiver adds (8th rd) | M9: 4
A10: Round 7 | B10: Rashee Rice | C10: WR | D10: KC | E10: 14.2 | F10: 2 | G10: 7 | H10: 5 | J10: Drafted 2025
